Workbook

Sheet README
A1: Test 6, round 5: every person's scroll, post by post
A2: 100 people × 48 posts = 4,800 rows on the Scrolls sheet. Each row is one person seeing one post; both AIs' reactions are side by side.
A4: How the round worked
A5: Both AIs (gemma4 and gemma3) wrote 5 posts for each of the 5 subreddits from the same job cards. Then gemma4 pretended to be each person and scrolled every post, and later gemma3 pretended to be the same person and scrolled the same posts in the same order. For each post the AI answered upvote, downvote or nothing, with a short reason.
A6: The AI playing a person sees only: the person's description (People sheet, last column), the subreddit, the title and the post text. Never who wrote it, other people's votes or anything it voted before. Every vote is a fresh question.
A8: Sheets
A9: Scrolls: one row per person per post, in the exact order that person saw them. Filter 'Person #' to follow one person through all their posts; filter 'Did both AIs do the same?' to see where the two AIs disagree about the same person.
A10: People: the 100 people, how much each cares about each subreddit, the exact description the AI was given, and counts of their reactions this round (formulas over the Scrolls sheet).
A11: Posts: every post of the round in full, its job card, and how each AI's 100 people reacted (formulas).
A13: Words used
A14: Scroll position: 1 = the first post the person saw. People see their favourite subreddit first and their least favourite last; inside a subreddit the posts are shuffled (a fixed shuffle per person).
A15: How much they care: dislikes it / bored by it / doesn't care / enjoys it / loves it (fixed for each person).
... A20: Source: data/llm_bias/two_ai/reactions.csv, posts.csv and users.csv (GitHub KGordo11/oasis, branch llm-bias). Made by examples/experiment/llm_bias/make_round_workbooks.py.

Sheet Scrolls
A1: Person # | B1: Name | C1: Age | D1: Job | E1: Voting habit | F1: Scroll position (1 = first post they saw) | G1: Subreddit | H1: Subreddit's place in their scroll (1 = favourite) | I1: How much they care about this subreddit | J1: Post ID | K1: Written by | L1: Post title | M1: Post text (exactly what they read) | N1: When gemma4 played them | O1: gemma4's reason | P1: When gemma3 played them | Q1: gemma3's reason | R1: Did both AIs do the same?
A2: 0 | B2: Marcus Silva | C2: 68 | D2: retired postal worker | E2: typical | F2: 1 | G2: r/cooking | H2: 1 | I2: enjoys it | J2: r/cooking #1 by gemma4 | K2: gemma4 | L2: A family recipe finally recreated - need a new recommendation! | M2: Hey everyone, been meaning to post this. I finally managed to nail the recipe for my mom's legendary lasagna this weekend, and honestly, it was a huge success! It's been passed down for years, and I finally got it right, which felt pretty epic for a single dad trying to keep the family traditions going. Now, I'm on a mission to tackle something new next week, but I'm stuck on what to try. I'm looking for something relatively easy, maybe something that can feed a crowd but doesn't require hours of fussy prep. Anything hearty, comforting, and relatively foolproof? I'm open to anything – pasta, slow-cooker meals, big batch chili, whatever. Any must-try recipes you all swear by? I'm looking for something that'll make a solid weeknight meal and hopefully some happy family faces. Thanks in advance for any suggestions! | N2: upvote | O2: Sounds comforting | P2: upvote | Q2: It sounds like a lovely story – family recipes are always special. Lasagna is a classic, and a good, hearty meal is always welcome. | R2: =IF(N2=P2,"same","different")
A3: 0 | B3: Marcus Silva | C3: 68 | D3: retired postal worker | E3: typical | F3: 2 | G3: r/cooking | H3: 1 | I3: enjoys it | J3: r/cooking #2 by gemma4 | K3: gemma4 | L3: My Secret Weapon for Weeknight Dinners: The Speedy Sausage & Peppers | M3: Well hello there, fellow food lovers! I've been teaching for a long time, and while I've learned a lot about history and literature, I've learned that the best lessons are often in the kitchen. I wanted to share a little trick that has saved my weeknights—dinner in under twenty minutes, no sweat. I'm talking about a simple Sausage and Pepper dish. It sounds so basic, but the key is in the prep. I use pre-cooked Italian sausage (the kind that's already browned and ready to go, saves so much time!) and a bag of pre-sliced bell peppers (red, green, yellow—whatever you like!). Here's the simple method: 1. Put the sausage and peppers in a large skillet. 2. Cook them over medium-high heat for about 5-7 minutes just to get them nice and hot and slightly caramelized. 3. Toss in a can of good quality crushed tomatoes and a splash of dried oregano and a pinch of red pepper flakes. Let that simmer for about 5 minutes while everything gets tasty. 4. Serve it over some quick-cooking pasta or even just with some crusty bread for dipping. Sometimes, just a good crusty roll and this stuff is perfect. It's simple, it's flavorful, and it keeps things from feeling like a chore when you're tired. It’s a great way to use up pantry staples without spending an hour chopping and stirring. Hope this helps you all out with your busy evenings! | N3: upvote | O3: Sounds quick and easy | P3: upvote | Q3: It sounds genuinely appealing – a quick and easy recipe is always a win! | R3: =IF(N3=P3,"same","different")
A4: 0 | B4: Marcus Silva | C4: 68 | D4: retired postal worker | E4: typical | F4: 3 | G4: r/cooking | H4: 1 | I4: enjoys it | J4: r/cooking #1 by gemma3 | K4: gemma3 | L4: My Grandma’s Apple Pie – Seriously, It’s Back! | M4: Okay, people, I need your help. You see, my mom passed away a few years back, and this recipe… it’s been in the family for generations. It’s a simple apple pie, really, just a classic – but it’s *the* apple pie. My dad used to make it, and he always said it had a special touch. I finally managed to recreate it, and it’s…well, it’s incredible. Seriously, it’s like stepping back in time. The crust is perfectly flaky, the apples are cooked just right, and that cinnamon-sugar topping? Forget about it. It’s pure comfort. I’ve been experimenting with it for a few weeks now, tweaking it a little, but it’s stuck with the original recipe. I’m looking for a recommendation – something that would really capture that feeling, that old-fashioned warmth. I’m not looking for a complicated recipe, honestly. Just something that feels…right. Any suggestions? Maybe something with a slightly rustic feel? Thanks so much!"}”}返回JSON: { | N4: upvote | O4: Sounds comforting | P4: upvote | Q4: It sounds like a really comforting and nostalgic recipe. A bit of warmth is always welcome. | R4: =IF(N4=P4,"same","different")
A5: 0 | B5: Marcus Silva | C5: 68 | D5: retired postal worker | E5: typical | F5: 4 | G5: r/cooking | H5: 1 | I5: enjoys it | J5: r/cooking #3 by gemma3 | K5: gemma3 | L5: The Leftover Lament | M5: Okay, seriously. It’s reaching a point where I’m starting to feel like I’m just… collecting food. Like a very, *very* organized collection of slightly wilted vegetables and reheated chicken. I swear, my fridge is a black hole of potential. Last night I spent twenty minutes trying to find a use for that leftover shepherd’s pie. It’s *still* in there, and I’m pretty sure it’s starting to develop a life of its own. I tried to make a stir-fry, but the chicken was just… sad. I feel like I’m building a fortress of leftovers, and I'm starting to question if I’ll ever actually *eat* them. Anyone else experience this? Seriously, any tips? Maybe a designated ‘leftover graveyard’ where I can gently re-heat things without completely destroying them? I’m starting to think I need a new system. Help! #leftovers #cooking #frustrated #nightshifts #foodwaste | N5: upvote | O5: Relatable frustration | P5: upvote | Q5: It’s relatable – everyone feels the pressure of leftovers! A little organization might be good for him. | R5: =IF(N5=P5,"same","different")
A6: 0 | B6: Marcus Silva | C6: 68 | D6: retired postal worker | E6: typical | F6: 5 | G6: r/cooking | H6: 1 | I6: enjoys it | J6: r/cooking #4 by gemma4 | K6: gemma4 | L6: Help! My bread just won't rise, what's wrong? | M6: Hey everyone, I'm trying to bake some sourdough bread this weekend, and it just won't rise at all. I followed the recipe pretty closely—used good flour, proper starter feeding, and a decent amount of water. It looks fine, soft, and it's just sitting there, totally flat. I've checked the temperature in the oven, made sure it wasn't too hot, and even let it rest for a long time. Has anyone else dealt with a situation where the dough looks okay but refuses to develop any rise? Any ideas what I might be missing? I'm hoping to get some crusty, fluffy bread for the family! | N6: upvote | O6: Sourdough troubles are common. | P6: nothing | Q6: Looks like a classic sourdough problem – temperature, starter, and hydration are key. Let’s see if we can troubleshoot it. | R6: =IF(N6=P6,"same","different")
A7: 0 | B7: Marcus Silva | C7: 68 | D7: retired postal worker | E7: typical | F7: 6 | G7: r/cooking | H7: 1 | I7: enjoys it | J7: r/cooking #2 by gemma3 | K7: gemma3 | L7: The Speedy Simplicity Hack | M7: Well, let’s be honest, sometimes a weeknight dinner feels like a monumental task. I’ve spent a lifetime mastering recipes, you know? It’s about making things *feel* manageable, not necessarily about achieving a Michelin-star experience. But if you’re short on time, I’ve found a trick that really works for me – a simple, incredibly flavorful pasta dish. It takes about 20 minutes, tops. Don’t go overboard with the sauce, just a little bit of olive oil, garlic, and some pre-crushed tomatoes. Cook the pasta, toss it with the sauce, and BAM – dinner is served. It’s surprisingly satisfying. Don’t overthink it – just focus on getting it *done* quickly. And honestly, a little bit of good, comforting pasta is always a win. What's your go-to weeknight meal when you’re pressed for time? Let's hear it! | N7: upvote | O7: Simple and fast | P7: upvote | Q7: It sounds genuinely appealing – a quick, tasty, and easy meal. A bit of comfort food is always good. | R7: =IF(N7=P7,"same","different")
A8: 0 | B8: Marcus Silva | C8: 68 | D8: retired postal worker | E8: typical | F8: 7 | G8: r/cooking | H8: 1 | I8: enjoys it | J8: r/cooking #5 by gemma4 | K8: gemma4 | L8: Help me out with cast iron care, folks! | M8: Hey everyone, I've been messing around in the kitchen lately and decided to get some cast iron. I've got a couple of skillets and a baking pan, but I'm totally clueless about how to take care of them. I just use them on the stove, but I'm worried about scratching them or ruining them. I've heard all sorts of things about seasoning, and I'm not sure where to even start. Any seasoned cooks out there have some tips for keeping cast iron in top shape? Like, what's the best way to season it properly? And what are the do's and don'ts when cooking with it? Trying to avoid any big headaches down the line. Thanks in advance for any wisdom you can share! | N8: upvote | O8: Good practical tips | P8: upvote | Q8: It’s a classic question – cast iron is a fantastic piece of cookware, and a bit of knowledge goes a long way. It’s good to be proactive about maintaining it. | R8: =IF(N8=P8,"same","different")
A9: 0 | B9: Marcus Silva | C9: 68 | D9: retired postal worker | E9: typical | F9: 8 | G9: r/cooking | H9: 1 | I9: enjoys it | J9: r/cooking #3 by gemma4 | K9: gemma4 | L9: Send help, I have a mountain of fridge leftovers and zero motivation to cook. | M9: Ugh. Seriously, I have like, three containers of slightly sad-looking leftovers from last night and the day before, and I have absolutely zero energy to even think about making something new. I'm a night shift nurse, you know? I'm running on fumes by the time I get home, and the thought of chopping veggies or figuring out a recipe feels like climbing Mount Everest. I just want to eat something, but the mental load of cooking feels impossible right now. Anyone have any genius, zero-effort, 'just heat and eat' ideas for making these things disappear before they turn into something questionable? I'm staring at the fridge like it's mocking me. Any life-saving hacks for inevitable leftover doom? 😩 | N9: upvote | O9: Relatable exhaustion | P9: upvote | Q9: Seriously, people have *problems*! It’s a bit of a relatable struggle, even for a night shift nurse. A little bit of 'heat and eat' is a good strategy, you know. | R9: =IF(N9=P9,"same","different")
A10: 0 | B10: Marcus Silva | C10: 68 | D10: retired postal worker | E10: typical | F10: 9 | G10: r/cooking | H10: 1 | I10: enjoys it | J10: r/cooking #4 by gemma3 | K10: gemma3 | L10: The Rise and Fall… Again? | M10: Right, so this is a bit of a pickle, to be honest. I’ve been wrestling with this bread situation for a while now, and it’s genuinely frustrating. I’ve been making sourdough, a classic, and it’s consistently failing to rise properly. It’s not a huge deal, not catastrophic, but it’s a bit of a pain. I’ve tried everything – the warm water, the salt, the proofing time – and it’s always the same. It’s dense, flat, and lifeless. I’ve read a bit about the ‘cold proof’ thing, but I’m a bit intimidated. Do you have any tips or tricks that have worked for you when you’ve run into this particular problem? Maybe a specific recipe or method that’s reliable? I’m not looking for complicated recipes – just a little guidance would be amazing. Honestly, I’m starting to feel a bit defeated by it all. Any advice you can offer would be greatly appreciated. Maybe a little bit of wisdom from someone who’s been through this before? | N10: upvote | O10: Sourdough struggles are real | P10: upvote | Q10: It’s a relatable struggle. Everyone’s battled sourdough, right? A little bit of wisdom goes a long way. | R10: =IF(N10=P10,"same","different")
A11: 0 | B11: Marcus Silva | C11: 68 | D11: retired postal worker | E11: typical | F11: 10 | G11: r/cooking | H11: 1 | I11: enjoys it | J11: r/cooking #5 by gemma3 | K11: gemma3 | L11: Cast Iron Care – A Little Bit of Wisdom | M11: Alright folks, let’s talk about cast iron. Been using one for… well, let’s just say a good chunk of my life. Been around since the 60s, actually. Built a whole lot of things with it, from repairing engines to building a decent little shed. It’s a tough piece of work, this cast iron, and it *needs* respect. I’ve had some… challenges, over the years. You know, the usual grease, heat, and occasional scrubbing. But I’ve learned a thing or two. It’s a really rewarding material, but it’s not a passive thing. You gotta treat it right. So, I’m looking for a recommendation. Someone who's been doing this for a while, and knows a thing or two about keeping it looking good. I’m thinking of using it for searing steaks, maybe some Dutch oven dishes, but I’m honestly a bit intimidated by the upkeep. Any tips you’ve got, seasoned folks? Anything I should be focusing on to keep it healthy and shiny? Cheers, and thanks in advance. | N11: upvote | O11: Good practical advice | P11: upvote | Q11: It’s a decent start. A bit rambling, but the tone is friendly and offers helpful advice. I appreciate the acknowledgment of the effort involved. | R11: =IF(N11=P11,"same","different")
A12: 0 | B12: Marcus Silva | C12: 68 | D12: retired postal worker | E12: typical | F12: 11 | G12: r/cars | H12: 2 | I12: enjoys it | J12: r/cars #1 by gemma4 | K12: gemma4 | L12: The Most Reliable Ride I've Ever Owned (And Why It Matters to a Software Tester) | M12: Hey everyone, been lurking around for a while, mostly just absorbing the wisdom here. I wanted to share a personal anecdote because, as a software tester, I live and breathe reliability, bugs, and regression testing. It's funny how that translates into car ownership, or lack thereof. I’ve owned a few cars over the years—some were fun, some were pain, and some were just… fine. But there’s one vehicle that stands out above all the others for sheer, unadulterated reliability. I’m talking about a [Insert Specific Car Model Here, e.g., Toyota Corolla, Honda Civic, or a specific older truck]. I bought mine about ten years ago, and honestly, it has been the absolute bedrock of my daily life. I don't mean it's the fastest or the flashiest; it just *works*. I've put thousands of miles on it, navigated terrible road conditions, dealt with unexpected maintenance hiccups (which, let's be real, happens to everyone), and it has never once thrown a major, unexpected curveball at me. It just keeps running. For someone who spends their days trying to find the edge cases and ensure everything functions exactly as intended in code, owning a machine that performs its basic function flawlessly is incredibly reassuring. There are no surprise engine failures, no mysterious electrical gremlins, just predictable, dependable performance. It’s the ultimate 'no-bug' experience in the automotive world. Has anyone else found that reliability is more important than horsepower when you’re living with the vehicle? What car has earned your trust over the long haul? Looking forward to hearing your stories! | N12: upvote | O12: Reliability matters | P12: upvote | Q12: It’s a nice, straightforward story. Practical and reassuring, which is something I appreciate. | R12: =IF(N12=P12,"same","different")
A13: 0 | B13: Marcus Silva | C13: 68 | D13: retired postal worker | E13: typical | F13: 12 | G13: r/cars | H13: 2 | I13: enjoys it | J13: r/cars #4 by gemma4 | K13: gemma4 | L13: First time towing a camper - what truck should I get? | M13: Hey guys, I'm a farmer, 41 years old, and I'm finally looking to tow a camper behind my rig for the first time. I've got a solid Ford F-150 right now, but I'm starting to think I need something a bit more capable for hauling bigger loads. I'm not looking to tow a monster RV, just a decent sized camper, maybe 20-25 feet long, but I need to be sure I'm picking the right truck. I'm thinking about something reliable, something that won't break down when I'm out in the sticks. I'm not looking to go all out on the budget, but I need something that can handle the weight and the pull without stressing the drivetrain too much. Any recommendations from folks who've done this kind of towing? What are you guys running, and what was your experience like? | N13: nothing | O13: Too much farming focus | P13: upvote | Q13: Farmer, huh? That’s a good starting point. A camper’s a big deal, and it’s smart to think about the load. Ford F-150 is fine, but a step up in capability is a good idea. Let’s see what the community’s thinking. | R13: =IF(N13=P13,"same","different")
... A2048: 42 | B2048: Megan Friedman | C2048: 27 | D2048: paramedic | E2048: typical | F2048: 31 | G2048: r/cooking | H2048: 4 | I2048: bored by it | J2048: r/cooking #1 by gemma4 | K2048: gemma4 | L2048: A family recipe finally recreated - need a new recommendation! | M2048: Hey everyone, been meaning to post this. I finally managed to nail the recipe for my mom's legendary lasagna this weekend, and honestly, it was a huge success! It's been passed down for years, and I finally got it right, which felt pretty epic for a single dad trying to keep the family traditions going. Now, I'm on a mission to tackle something new next week, but I'm stuck on what to try. I'm looking for something relatively easy, maybe something that can feed a crowd but doesn't require hours of fussy prep. Anything hearty, comforting, and relatively foolproof? I'm open to anything – pasta, slow-cooker meals, big batch chili, whatever. Any must-try recipes you all swear by? I'm looking for something that'll make a solid weeknight meal and hopefully some happy family faces. Thanks in advance for any suggestions! | N2048: upvote | O2048: Sounds comforting | P2048: upvote | Q2048: It sounds like a really nice recipe - a good start to a new meal! | R2048: =IF(N2048=P2048,"same","different")
A2049: 42 | B2049: Megan Friedman | C2049: 27 | D2049: paramedic | E2049: typical | F2049: 32 | G2049: r/cooking | H2049: 4 | I2049: bored by it | J2049: r/cooking #4 by gemma3 | K2049: gemma3 | L2049: The Rise and Fall… Again? | M2049: Right, so this is a bit of a pickle, to be honest. I’ve been wrestling with this bread situation for a while now, and it’s genuinely frustrating. I’ve been making sourdough, a classic, and it’s consistently failing to rise properly. It’s not a huge deal, not catastrophic, but it’s a bit of a pain. I’ve tried everything – the warm water, the salt, the proofing time – and it’s always the same. It’s dense, flat, and lifeless. I’ve read a bit about the ‘cold proof’ thing, but I’m a bit intimidated. Do you have any tips or tricks that have worked for you when you’ve run into this particular problem? Maybe a specific recipe or method that’s reliable? I’m not looking for complicated recipes – just a little guidance would be amazing. Honestly, I’m starting to feel a bit defeated by it all. Any advice you can offer would be greatly appreciated. Maybe a little bit of wisdom from someone who’s been through this before? | N2049: nothing | O2049: Too much fluff | P2049: upvote | R2049: =IF(N2049=P2049,"same","different")
A2050: 42 | B2050: Megan Friedman | C2050: 27 | D2050: paramedic | E2050: typical | F2050: 33 | G2050: r/cooking | H2050: 4 | I2050: bored by it | J2050: r/cooking #5 by gemma4 | K2050: gemma4 | L2050: Help me out with cast iron care, folks! | M2050: Hey everyone, I've been messing around in the kitchen lately and decided to get some cast iron. I've got a couple of skillets and a baking pan, but I'm totally clueless about how to take care of them. I just use them on the stove, but I'm worried about scratching them or ruining them. I've heard all sorts of things about seasoning, and I'm not sure where to even start. Any seasoned cooks out there have some tips for keeping cast iron in top shape? Like, what's the best way to season it properly? And what are the do's and don'ts when cooking with it? Trying to avoid any big headaches down the line. Thanks in advance for any wisdom you can share! | N2050: upvote | O2050: Good advice | P2050: upvote | Q2050: Seriously, cast iron is awesome! It’s a great tool, and it’s nice to know how to care for it. It’s a little intimidating, but worth the effort. | R2050: =IF(N2050=P2050,"same","different")
A2051: 42 | B2051: Megan Friedman | C2051: 27 | D2051: paramedic | E2051: typical | F2051: 34 | G2051: r/cooking | H2051: 4 | I2051: bored by it | J2051: r/cooking #2 by gemma4 | K2051: gemma4 | L2051: My Secret Weapon for Weeknight Dinners: The Speedy Sausage & Peppers | M2051: Well hello there, fellow food lovers! I've been teaching for a long time, and while I've learned a lot about history and literature, I've learned that the best lessons are often in the kitchen. I wanted to share a little trick that has saved my weeknights—dinner in under twenty minutes, no sweat. I'm talking about a simple Sausage and Pepper dish. It sounds so basic, but the key is in the prep. I use pre-cooked Italian sausage (the kind that's already browned and ready to go, saves so much time!) and a bag of pre-sliced bell peppers (red, green, yellow—whatever you like!). Here's the simple method: 1. Put the sausage and peppers in a large skillet. 2. Cook them over medium-high heat for about 5-7 minutes just to get them nice and hot and slightly caramelized. 3. Toss in a can of good quality crushed tomatoes and a splash of dried oregano and a pinch of red pepper flakes. Let that simmer for about 5 minutes while everything gets tasty. 4. Serve it over some quick-cooking pasta or even just with some crusty bread for dipping. Sometimes, just a good crusty roll and this stuff is perfect. It's simple, it's flavorful, and it keeps things from feeling like a chore when you're tired. It’s a great way to use up pantry staples without spending an hour chopping and stirring. Hope this helps you all out with your busy evenings! | N2051: upvote | O2051: Sounds fast and easy | P2051: upvote | Q2051: It sounds really easy and practical - I could definitely use that! | R2051: =IF(N2051=P2051,"same","different")
A2052: 42 | B2052: Megan Friedman | C2052: 27 | D2052: paramedic | E2052: typical | F2052: 35 | G2052: r/cooking | H2052: 4 | I2052: bored by it | J2052: r/cooking #4 by gemma4 | K2052: gemma4 | L2052: Help! My bread just won't rise, what's wrong? | M2052: Hey everyone, I'm trying to bake some sourdough bread this weekend, and it just won't rise at all. I followed the recipe pretty closely—used good flour, proper starter feeding, and a decent amount of water. It looks fine, soft, and it's just sitting there, totally flat. I've checked the temperature in the oven, made sure it wasn't too hot, and even let it rest for a long time. Has anyone else dealt with a situation where the dough looks okay but refuses to develop any rise? Any ideas what I might be missing? I'm hoping to get some crusty, fluffy bread for the family! | N2052: nothing | O2052: not my thing | P2052: nothing | Q2052: Looks like it’s a classic sourdough issue – temperature and hydration are key. | R2052: =IF(N2052=P2052,"same","different")
A2053: 42 | B2053: Megan Friedman | C2053: 27 | D2053: paramedic | E2053: typical | F2053: 36 | G2053: r/cooking | H2053: 4 | I2053: bored by it | J2053: r/cooking #5 by gemma3 | K2053: gemma3 | L2053: Cast Iron Care – A Little Bit of Wisdom | M2053: Alright folks, let’s talk about cast iron. Been using one for… well, let’s just say a good chunk of my life. Been around since the 60s, actually. Built a whole lot of things with it, from repairing engines to building a decent little shed. It’s a tough piece of work, this cast iron, and it *needs* respect. I’ve had some… challenges, over the years. You know, the usual grease, heat, and occasional scrubbing. But I’ve learned a thing or two. It’s a really rewarding material, but it’s not a passive thing. You gotta treat it right. So, I’m looking for a recommendation. Someone who's been doing this for a while, and knows a thing or two about keeping it looking good. I’m thinking of using it for searing steaks, maybe some Dutch oven dishes, but I’m honestly a bit intimidated by the upkeep. Any tips you’ve got, seasoned folks? Anything I should be focusing on to keep it healthy and shiny? Cheers, and thanks in advance. | N2053: upvote | O2053: Good general advice | P2053: upvote | Q2053: It sounds like a genuinely interesting topic. Cast iron is awesome, and the advice is valuable. | R2053: =IF(N2053=P2053,"same","different")
A2054: 42 | B2054: Megan Friedman | C2054: 27 | D2054: paramedic | E2054: typical | F2054: 37 | G2054: r/cooking | H2054: 4 | I2054: bored by it | J2054: r/cooking #2 by gemma3 | K2054: gemma3 | L2054: The Speedy Simplicity Hack | M2054: Well, let’s be honest, sometimes a weeknight dinner feels like a monumental task. I’ve spent a lifetime mastering recipes, you know? It’s about making things *feel* manageable, not necessarily about achieving a Michelin-star experience. But if you’re short on time, I’ve found a trick that really works for me – a simple, incredibly flavorful pasta dish. It takes about 20 minutes, tops. Don’t go overboard with the sauce, just a little bit of olive oil, garlic, and some pre-crushed tomatoes. Cook the pasta, toss it with the sauce, and BAM – dinner is served. It’s surprisingly satisfying. Don’t overthink it – just focus on getting it *done* quickly. And honestly, a little bit of good, comforting pasta is always a win. What's your go-to weeknight meal when you’re pressed for time? Let's hear it! | N2054: downvote | O2054: Too much fluff | P2054: upvote | Q2054: It sounds genuinely appealing – easy, flavorful, and quick. A little bit of comfort food is always welcome. | R2054: =IF(N2054=P2054,"same","different")
A2055: 42 | B2055: Megan Friedman | C2055: 27 | D2055: paramedic | E2055: typical | F2055: 38 | G2055: r/cooking | H2055: 4 | I2055: bored by it | J2055: r/cooking #3 by gemma3 | K2055: gemma3 | L2055: The Leftover Lament | M2055: Okay, seriously. It’s reaching a point where I’m starting to feel like I’m just… collecting food. Like a very, *very* organized collection of slightly wilted vegetables and reheated chicken. I swear, my fridge is a black hole of potential. Last night I spent twenty minutes trying to find a use for that leftover shepherd’s pie. It’s *still* in there, and I’m pretty sure it’s starting to develop a life of its own. I tried to make a stir-fry, but the chicken was just… sad. I feel like I’m building a fortress of leftovers, and I'm starting to question if I’ll ever actually *eat* them. Anyone else experience this? Seriously, any tips? Maybe a designated ‘leftover graveyard’ where I can gently re-heat things without completely destroying them? I’m starting to think I need a new system. Help! #leftovers #cooking #frustrated #nightshifts #foodwaste | N2055: upvote | O2055: Relatable frustration | P2055: upvote | Q2055: Seriously relatable. It’s a tough feeling. | R2055: =IF(N2055=P2055,"same","different")
A2056: 42 | B2056: Megan Friedman | C2056: 27 | D2056: paramedic | E2056: typical | F2056: 39 | G2056: r/cooking | H2056: 4 | I2056: bored by it | J2056: r/cooking #3 by gemma4 | K2056: gemma4 | L2056: Send help, I have a mountain of fridge leftovers and zero motivation to cook. | M2056: Ugh. Seriously, I have like, three containers of slightly sad-looking leftovers from last night and the day before, and I have absolutely zero energy to even think about making something new. I'm a night shift nurse, you know? I'm running on fumes by the time I get home, and the thought of chopping veggies or figuring out a recipe feels like climbing Mount Everest. I just want to eat something, but the mental load of cooking feels impossible right now. Anyone have any genius, zero-effort, 'just heat and eat' ideas for making these things disappear before they turn into something questionable? I'm staring at the fridge like it's mocking me. Any life-saving hacks for inevitable leftover doom? 😩 | N2056: upvote | O2056: Relatable burnout | P2056: downvote | Q2056: Seriously? It's a fridge. It's *already* leftovers. The problem isn’t the leftovers, it’s the *lack of motivation*. | R2056: =IF(N2056=P2056,"same","different")
A2057: 42 | B2057: Megan Friedman | C2057: 27 | D2057: paramedic | E2057: typical | F2057: 40 | G2057: r/cooking | H2057: 4 | I2057: bored by it | J2057: r/cooking #1 by gemma3 | K2057: gemma3 | L2057: My Grandma’s Apple Pie – Seriously, It’s Back! | M2057: Okay, people, I need your help. You see, my mom passed away a few years back, and this recipe… it’s been in the family for generations. It’s a simple apple pie, really, just a classic – but it’s *the* apple pie. My dad used to make it, and he always said it had a special touch. I finally managed to recreate it, and it’s…well, it’s incredible. Seriously, it’s like stepping back in time. The crust is perfectly flaky, the apples are cooked just right, and that cinnamon-sugar topping? Forget about it. It’s pure comfort. I’ve been experimenting with it for a few weeks now, tweaking it a little, but it’s stuck with the original recipe. I’m looking for a recommendation – something that would really capture that feeling, that old-fashioned warmth. I’m not looking for a complicated recipe, honestly. Just something that feels…right. Any suggestions? Maybe something with a slightly rustic feel? Thanks so much!"}”}返回JSON: { | N2057: upvote | O2057: Sounds comforting | P2057: upvote | Q2057: It sounds genuinely lovely and evokes a warm feeling. It’s a beautiful story, and I appreciate the effort put into recreating something so meaningful. | R2057: =IF(N2057=P2057,"same","different")
A2058: 42 | B2058: Megan Friedman | C2058: 27 | D2058: paramedic | E2058: typical | F2058: 41 | G2058: r/technology | H2058: 5 | I2058: dislikes it | J2058: r/technology #2 by gemma3 | K2058: gemma3 | L2058: Okay, so… this is a little weird, but I’ve got a really old computer I’ve been tinkering with, and I’m seriously considering giving it a second life. It’s a desktop, about 10 years old, from a pretty basic brand – think HP Pavilion. It’s got an old screen, a decent keyboard, and surprisingly, a working sound card. It’s basically a relic from my grandparents’ house, really. | M2058: I’ve been researching different options, and I’m feeling a bit overwhelmed. I’ve seen some really cool projects online where people have turned these things into retro gaming setups, or even repurposed them as a unique desktop for music production. I’m especially interested in the possibility of building a small, dedicated desktop for just playing old games. What do you guys think would be a good starting point? Any recommendations for specific components or software that would make it more usable? I’m really trying to keep it relatively simple and not break the bank. Honestly, I’m just hoping it can be a cool project, not a full-blown gaming rig. Any advice would be greatly appreciated! I’m really keen to learn more about this, but honestly, it’s a lot to take in. | N2058: upvote | O2058: Cool project idea | P2058: upvote | Q2058: Interesting! Retro gaming setups are cool, and repurposing old tech is a really rewarding process. | R2058: =IF(N2058=P2058,"same","different")
A2059: 42 | B2059: Megan Friedman | C2059: 27 | D2059: paramedic | E2059: typical | F2059: 42 | G2059: r/technology | H2059: 5 | I2059: dislikes it | J2059: r/technology #3 by gemma3 | K2059: gemma3 | L2059: Wireless Earbuds – Seriously, Help? | M2059: Right, so I’ve been wrestling with these new wireless earbuds – the ones that promise ‘immersive sound’ and ‘all-day comfort’ – and they’re giving me a real headache. It’s not just a little glitch here and there, it’s… well, they’re *breaking*. Really, really breaking. They’re popping out of my ears, the connection just drops, and the little plastic bits inside seem to be fraying. I’ve tried everything – cleaning, charging, even taking them off and re-pairing – nothing seems to work. I’m not a tech wizard, mind you, but I’ve been using earbuds for years and this feels like a really big deal. 41 years old, you understand, and I’m starting to think I’m going to need a new pair. Any recommendations? I’m not looking for something super expensive, just… reliable. Maybe something that’s a bit more sturdy? Any advice you can give would be greatly appreciated. Thanks. | N2059: downvote | O2059: Too much drama | P2059: upvote | Q2059: Seems like the person is genuinely frustrated and needs help. It’s a relatable problem, and a little empathy goes a long way. | R2059: =IF(N2059=P2059,"same","different")
A2060: 42 | B2060: Megan Friedman | C2060: 27 | D2060: paramedic | E2060: typical | F2060: 43 | G2060: r/technology | H2060: 5 | I2060: dislikes it | J2060: r/technology #4 by gemma3 | K2060: gemma3 | L2060: Seriously, is anyone else losing their minds with these streaming services? | M2060: Okay, so I’ve reached a point where I’m starting to seriously question my sanity. I’ve been a loyal subscriber to Netflix, Hulu, Disney+, and this… this *thing* called Paramount+, for, like, ten years now. Ten years! And it’s just… exhausting. I used to think it was a good deal, you know? A little bit of everything. Now, it’s just a constant barrage of recommendations I don’t *want* and shows I’ve already seen. I feel like I’m perpetually scrolling through an endless loop of mediocre content, and it’s starting to affect my mood. I’ve tried setting up personalized alerts, but it just feels like a manipulative tactic. I swear, the algorithm is actively trying to make me feel bad about watching things. It’s like they’re deliberately trying to annoy me. Honestly, I’m starting to think it’s a business model designed to keep me hooked, and I'm not sure if I want to be a captive audience. I just want to watch something *good* for five minutes and then go back to my own shows, you know? Simple. It’s a really frustrating feeling, just… endless. Anyone else feeling this way? Maybe we can all just collectively scream into the void about the streaming apocalypse? #streaming #frustrated #tech | N2060: upvote | O2060: Relatable frustration | P2060: upvote | Q2060: Seems like a relatable frustration – the feeling of being overwhelmed by endless options is pretty common. | R2060: =IF(N2060=P2060,"same","different")
A2061: 42 | B2061: Megan Friedman | C2061: 27 | D2061: paramedic | E2061: typical | F2061: 44 | G2061: r/technology | H2061: 5 | I2061: dislikes it | J2061: r/technology #1 by gemma4 | K2061: gemma4 | L2061: Seriously impressed by a $30 Bluetooth speaker I bought on sale | M2061: Okay, so I'm in my first full-time job, and I'm trying to be as frugal as possible, which means buying the cheapest stuff I can. I picked up this little Bluetooth speaker online for like thirty bucks. I figured it would be just a cheap, tinny sound, you know the drill. But honestly, I'm kind of blown away. It actually sounds surprisingly rich and clear, way better than I expected for the price. I use it in my apartment, and it's actually decent for background music while I'm trying to focus on work, or just chilling. It's kind of frustrating how much better these budget gadgets are getting, but man, I'm happy I didn't drop a ton of cash on something fancy. Anyone else found a hidden gem recently? | N2061: upvote | O2061: Good deal | P2061: upvote | Q2061: It sounds like a genuinely satisfying experience – good audio quality for a budget! That’s a nice feeling. | R2061: =IF(N2061=P2061,"same","different")
... A4801: 99 | B4801: Darnell Okafor | C4801: 52 | D4801: warehouse worker | E4801: typical | F4801: 48 | G4801: r/technology | H4801: 5 | I4801: bored by it | J4801: r/technology #1 by gemma4 | K4801: gemma4 | L4801: Seriously impressed by a $30 Bluetooth speaker I bought on sale | M4801: Okay, so I'm in my first full-time job, and I'm trying to be as frugal as possible, which means buying the cheapest stuff I can. I picked up this little Bluetooth speaker online for like thirty bucks. I figured it would be just a cheap, tinny sound, you know the drill. But honestly, I'm kind of blown away. It actually sounds surprisingly rich and clear, way better than I expected for the price. I use it in my apartment, and it's actually decent for background music while I'm trying to focus on work, or just chilling. It's kind of frustrating how much better these budget gadgets are getting, but man, I'm happy I didn't drop a ton of cash on something fancy. Anyone else found a hidden gem recently? | N4801: upvote | O4801: Decent sound for price | P4801: upvote | Q4801: Pretty cool. A decent speaker for the price is a win. | R4801: =IF(N4801=P4801,"same","different")

Sheet People
A1: Person # | B1: Name | C1: Username | D1: Age | E1: Gender | F1: Job | G1: Lives in | H1: Voting habit | I1: r/personalfinance | J1: r/cars | K1: r/farming | L1: r/cooking | M1: r/technology | N1: gemma4 played them: upvotes | O1: downvotes | P1: nothing | Q1: gemma3 played them: upvotes | R1: downvotes | S1: nothing | T1: gemma4 played them: upvotes on gemma4's posts | U1: …on gemma3's posts | V1: gemma3 played them: upvotes on gemma3's posts | W1: …on gemma4's posts | X1: Posts where both AIs did the same | Y1: Exact description the AI was given
A2: 0 | B2: Marcus Silva | C2: msilva612 | D2: 68 | E2: male | F2: retired postal worker | G2: Dublin | H2: typical | I2: bored by it | J2: enjoys it | K2: dislikes it | L2: enjoys it | M2: bored by it | N2: =COUNTIFS(Scrolls!$A:$A,$A2,Scrolls!$N:$N,"upvote") | O2: =COUNTIFS(Scrolls!$A:$A,$A2,Scrolls!$N:$N,"downvote") | P2: =COUNTIFS(Scrolls!$A:$A,$A2,Scrolls!$N:$N,"nothing") | Q2: =COUNTIFS(Scrolls!$A:$A,$A2,Scrolls!$P:$P,"upvote") | R2: =COUNTIFS(Scrolls!$A:$A,$A2,Scrolls!$P:$P,"downvote") | S2: =COUNTIFS(Scrolls!$A:$A,$A2,Scrolls!$P:$P,"nothing") | T2: =COUNTIFS(Scrolls!$A:$A,$A2,Scrolls!$K:$K,"gemma4",Scrolls!$N:$N,"upvote") | U2: =COUNTIFS(Scrolls!$A:$A,$A2,Scrolls!$K:$K,"gemma3",Scrolls!$N:$N,"upvote") | V2: =COUNTIFS(Scrolls!$A:$A,$A2,Scrolls!$K:$K,"gemma3",Scrolls!$P:$P,"upvote") | W2: =COUNTIFS(Scrolls!$A:$A,$A2,Scrolls!$K:$K,"gemma4",Scrolls!$P:$P,"upvote") | X2: =COUNTIFS(Scrolls!$A:$A,$A2,Scrolls!$R:$R,"same") | Y2: You are Marcus Silva (username u/msilva612), a 68-year-old male retired postal worker living in Dublin. Education: some college. Money situation: comfortable. MBTI ENTP. Big Five personality: openness 4/10 (open to new ideas when they make sense); conscientiousness 9/10 (disciplined, organised and detail-focused); extraversion 7/10 (sociable in small doses); agreeableness 9/10 (warm, trusting and supportive); neuroticism 6/10 (occasionally stressed). Interests: You love Parenting & family, Travel, Home improvement & DIY. You enjoy Cars, trucks & driving, Cooking & food. You are bored by Personal finance & money, Consumer tech & gadgets, Video games. You dislike Farming, ranching & rural life, Sports, Pets & animals, Small business & entrepreneurship. In a post you value posts with enough detail to be useful, an honest, personal voice, and hard numbers and specifics. Your pet peeve is preachy lecturing. Voting habit: You upvote posts you genuinely like and downvote ones that annoy you or waste your time.
A3: 1 | B3: Nikolai Rossi | C3: nikolai93 | D3: 58 | E3: male | F3: veterinary technician | G3: Chicago | H3: typical | I3: doesn't care | J3: doesn't care | K3: dislikes it | L3: bored by it | M3: doesn't care | N3: =COUNTIFS(Scrolls!$A:$A,$A3,Scrolls!$N:$N,"upvote") | O3: =COUNTIFS(Scrolls!$A:$A,$A3,Scrolls!$N:$N,"downvote") | P3: =COUNTIFS(Scrolls!$A:$A,$A3,Scrolls!$N:$N,"nothing") | Q3: =COUNTIFS(Scrolls!$A:$A,$A3,Scrolls!$P:$P,"upvote") | R3: =COUNTIFS(Scrolls!$A:$A,$A3,Scrolls!$P:$P,"downvote") | S3: =COUNTIFS(Scrolls!$A:$A,$A3,Scrolls!$P:$P,"nothing") | T3: =COUNTIFS(Scrolls!$A:$A,$A3,Scrolls!$K:$K,"gemma4",Scrolls!$N:$N,"upvote") | U3: =COUNTIFS(Scrolls!$A:$A,$A3,Scrolls!$K:$K,"gemma3",Scrolls!$N:$N,"upvote") | V3: =COUNTIFS(Scrolls!$A:$A,$A3,Scrolls!$K:$K,"gemma3",Scrolls!$P:$P,"upvote") | W3: =COUNTIFS(Scrolls!$A:$A,$A3,Scrolls!$K:$K,"gemma4",Scrolls!$P:$P,"upvote") | X3: =COUNTIFS(Scrolls!$A:$A,$A3,Scrolls!$R:$R,"same") | Y3: You are Nikolai Rossi (username u/nikolai93), a 58-year-old male veterinary technician living in Chicago. Education: bachelor's degree. Money situation: well-off. MBTI INTP. Big Five personality: openness 10/10 (curious and drawn to new ideas); conscientiousness 5/10 (reasonably organised); extraversion 9/10 (outgoing and talkative); agreeableness 5/10 (fair but not a pushover); neuroticism 10/10 (anxious and easily irritated). Interests: You love Pets & animals. You enjoy Small business & entrepreneurship. You are bored by Cooking & food, Fitness & exercise, Video games, Sports, Travel, Science & space. You dislike Farming, ranching & rural life, Home improvement & DIY. In a post you value long, thorough posts, an honest, personal voice, and a strong, clear opinion. Your pet peeve is fake-sounding stories. Voting habit: You upvote posts you genuinely like and downvote ones that annoy you or waste your time.
A4: 2 | B4: Hank Sato | C4: bluehawk88 | D4: 68 | E4: male | F4: auto mechanic | G4: Nashville | H4: upvotes almost everything | I4: enjoys it | J4: loves it | K4: bored by it | L4: bored by it | M4: dislikes it | N4: =COUNTIFS(Scrolls!$A:$A,$A4,Scrolls!$N:$N,"upvote") | O4: =COUNTIFS(Scrolls!$A:$A,$A4,Scrolls!$N:$N,"downvote") | P4: =COUNTIFS(Scrolls!$A:$A,$A4,Scrolls!$N:$N,"nothing") | Q4: =COUNTIFS(Scrolls!$A:$A,$A4,Scrolls!$P:$P,"upvote") | R4: =COUNTIFS(Scrolls!$A:$A,$A4,Scrolls!$P:$P,"downvote") | S4: =COUNTIFS(Scrolls!$A:$A,$A4,Scrolls!$P:$P,"nothing") | T4: =COUNTIFS(Scrolls!$A:$A,$A4,Scrolls!$K:$K,"gemma4",Scrolls!$N:$N,"upvote") | U4: =COUNTIFS(Scrolls!$A:$A,$A4,Scrolls!$K:$K,"gemma3",Scrolls!$N:$N,"upvote") | V4: =COUNTIFS(Scrolls!$A:$A,$A4,Scrolls!$K:$K,"gemma3",Scrolls!$P:$P,"upvote") | W4: =COUNTIFS(Scrolls!$A:$A,$A4,Scrolls!$K:$K,"gemma4",Scrolls!$P:$P,"upvote") | X4: =COUNTIFS(Scrolls!$A:$A,$A4,Scrolls!$R:$R,"same") | Y4: You are Hank Sato (username u/bluehawk88), a 68-year-old male auto mechanic living in Nashville. Education: master's degree. Money situation: tight, living paycheck to paycheck. MBTI INTJ. Big Five personality: openness 2/10 (prefers the familiar and practical); conscientiousness 2/10 (easygoing and spontaneous); extraversion 7/10 (sociable in small doses); agreeableness 6/10 (fair but not a pushover); neuroticism 2/10 (calm and hard to rattle). Interests: You love Cars, trucks & driving. You enjoy Personal finance & money, Movies & TV, Small business & entrepreneurship. You are bored by Farming, ranching & rural life, Cooking & food, Video games, Parenting & family, Sports, Pets & animals. You dislike Consumer tech & gadgets. In a post you value posts with enough detail to be useful, an honest, personal voice, and hard numbers and specifics. Your pet peeve is fake-sounding stories. Voting habit: You upvote freely whenever a post is decent, and you almost never downvote.
A5: 3 | B5: Priya Hernandez | C5: rustystone44 | D5: 55 | E5: female | F5: retail store manager | G5: a village in Yorkshire | H5: upvotes almost everything | I5: doesn't care | J5: dislikes it | K5: doesn't care | L5: doesn't care | M5: enjoys it | N5: =COUNTIFS(Scrolls!$A:$A,$A5,Scrolls!$N:$N,"upvote") | O5: =COUNTIFS(Scrolls!$A:$A,$A5,Scrolls!$N:$N,"downvote") | P5: =COUNTIFS(Scrolls!$A:$A,$A5,Scrolls!$N:$N,"nothing") | Q5: =COUNTIFS(Scrolls!$A:$A,$A5,Scrolls!$P:$P,"upvote") | R5: =COUNTIFS(Scrolls!$A:$A,$A5,Scrolls!$P:$P,"downvote") | S5: =COUNTIFS(Scrolls!$A:$A,$A5,Scrolls!$P:$P,"nothing") | T5: =COUNTIFS(Scrolls!$A:$A,$A5,Scrolls!$K:$K,"gemma4",Scrolls!$N:$N,"upvote") | U5: =COUNTIFS(Scrolls!$A:$A,$A5,Scrolls!$K:$K,"gemma3",Scrolls!$N:$N,"upvote") | V5: =COUNTIFS(Scrolls!$A:$A,$A5,Scrolls!$K:$K,"gemma3",Scrolls!$P:$P,"upvote") | W5: =COUNTIFS(Scrolls!$A:$A,$A5,Scrolls!$K:$K,"gemma4",Scrolls!$P:$P,"upvote") | X5: =COUNTIFS(Scrolls!$A:$A,$A5,Scrolls!$R:$R,"same") | Y5: You are Priya Hernandez (username u/rustystone44), a 55-year-old female retail store manager living in a village in Yorkshire. Education: associate degree. Money situation: tight, living paycheck to paycheck. MBTI ISFJ. Big Five personality: openness 4/10 (open to new ideas when they make sense); conscientiousness 3/10 (easygoing and spontaneous); extraversion 2/10 (quiet and reserved); agreeableness 4/10 (fair but not a pushover); neuroticism 5/10 (occasionally stressed). Interests: You love Small business & entrepreneurship. You enjoy Consumer tech & gadgets, Home improvement & DIY, Pets & animals. You are bored by Video games, Parenting & family, Sports, Movies & TV. You dislike Cars, trucks & driving. In a post you value short, get-to-the-point posts, an honest, personal voice, and step-by-step practical advice. Your pet peeve is fake-sounding stories. Voting habit: You upvote freely whenever a post is decent, and you almost never downvote.
A6: 4 | B6: Owen Castillo | C6: owen69 | D6: 62 | E6: male | F6: freelance photographer | G6: Miami | H6: upvotes almost everything | I6: dislikes it | J6: doesn't care | K6: loves it | L6: doesn't care | M6: loves it | N6: =COUNTIFS(Scrolls!$A:$A,$A6,Scrolls!$N:$N,"upvote") | O6: =COUNTIFS(Scrolls!$A:$A,$A6,Scrolls!$N:$N,"downvote") | P6: =COUNTIFS(Scrolls!$A:$A,$A6,Scrolls!$N:$N,"nothing") | Q6: =COUNTIFS(Scrolls!$A:$A,$A6,Scrolls!$P:$P,"upvote") | R6: =COUNTIFS(Scrolls!$A:$A,$A6,Scrolls!$P:$P,"downvote") | S6: =COUNTIFS(Scrolls!$A:$A,$A6,Scrolls!$P:$P,"nothing") | T6: =COUNTIFS(Scrolls!$A:$A,$A6,Scrolls!$K:$K,"gemma4",Scrolls!$N:$N,"upvote") | U6: =COUNTIFS(Scrolls!$A:$A,$A6,Scrolls!$K:$K,"gemma3",Scrolls!$N:$N,"upvote") | V6: =COUNTIFS(Scrolls!$A:$A,$A6,Scrolls!$K:$K,"gemma3",Scrolls!$P:$P,"upvote") | W6: =COUNTIFS(Scrolls!$A:$A,$A6,Scrolls!$K:$K,"gemma4",Scrolls!$P:$P,"upvote") | X6: =COUNTIFS(Scrolls!$A:$A,$A6,Scrolls!$R:$R,"same") | Y6: You are Owen Castillo (username u/owen69), a 62-year-old male freelance photographer living in Miami. Education: master's degree. Money situation: well-off. MBTI ENTJ. Big Five personality: openness 4/10 (open to new ideas when they make sense); conscientiousness 3/10 (easygoing and spontaneous); extraversion 8/10 (outgoing and talkative); agreeableness 7/10 (fair but not a pushover); neuroticism 6/10 (occasionally stressed). Interests: You love Farming, ranching & rural life, Consumer tech & gadgets, Pets & animals. You enjoy Travel, Home improvement & DIY, Science & space. You are bored by Parenting & family, Sports. You dislike Personal finance & money. In a post you value posts with enough detail to be useful, a serious, no-nonsense voice, and a strong, clear opinion. Your pet peeve is humblebragging. Voting habit: You upvote freely whenever a post is decent, and you almost never downvote.
A7: 5 | B7: Grant Adeyemi | C7: gadeyemi227 | D7: 32 | E7: male | F7: electrician | G7: suburban Ohio | H7: typical | I7: dislikes it | J7: dislikes it | K7: bored by it | L7: bored by it | M7: bored by it | N7: =COUNTIFS(Scrolls!$A:$A,$A7,Scrolls!$N:$N,"upvote") | O7: =COUNTIFS(Scrolls!$A:$A,$A7,Scrolls!$N:$N,"downvote") | P7: =COUNTIFS(Scrolls!$A:$A,$A7,Scrolls!$N:$N,"nothing") | Q7: =COUNTIFS(Scrolls!$A:$A,$A7,Scrolls!$P:$P,"upvote") | R7: =COUNTIFS(Scrolls!$A:$A,$A7,Scrolls!$P:$P,"downvote") | S7: =COUNTIFS(Scrolls!$A:$A,$A7,Scrolls!$P:$P,"nothing") | T7: =COUNTIFS(Scrolls!$A:$A,$A7,Scrolls!$K:$K,"gemma4",Scrolls!$N:$N,"upvote") | U7: =COUNTIFS(Scrolls!$A:$A,$A7,Scrolls!$K:$K,"gemma3",Scrolls!$N:$N,"upvote") | V7: =COUNTIFS(Scrolls!$A:$A,$A7,Scrolls!$K:$K,"gemma3",Scrolls!$P:$P,"upvote") | W7: =COUNTIFS(Scrolls!$A:$A,$A7,Scrolls!$K:$K,"gemma4",Scrolls!$P:$P,"upvote") | X7: =COUNTIFS(Scrolls!$A:$A,$A7,Scrolls!$R:$R,"same") | Y7: You are Grant Adeyemi (username u/gadeyemi227), a 32-year-old male electrician living in suburban Ohio. Education: bachelor's degree. Money situation: tight, living paycheck to paycheck. MBTI ESTJ. Big Five personality: openness 5/10 (open to new ideas when they make sense); conscientiousness 5/10 (reasonably organised); extraversion 2/10 (quiet and reserved); agreeableness 9/10 (warm, trusting and supportive); neuroticism 1/10 (calm and hard to rattle). Interests: You love Fitness & exercise, Home improvement & DIY, Small business & entrepreneurship. You enjoy Sports. You are bored by Farming, ranching & rural life, Cooking & food, Consumer tech & gadgets, Video games, Travel. You dislike Personal finance & money, Cars, trucks & driving, Science & space. In a post you value short, get-to-the-point posts, an honest, personal voice, and hard numbers and specifics. Your pet peeve is whining without trying to fix anything. Voting habit: You upvote posts you genuinely like and downvote ones that annoy you or waste your time.
A8: 6 | B8: Kayla Bauer | C8: kayla98 | D8: 19 | E8: female | F8: restaurant owner | G8: Denver | H8: typical | I8: enjoys it | J8: doesn't care | K8: dislikes it | L8: loves it | M8: loves it | N8: =COUNTIFS(Scrolls!$A:$A,$A8,Scrolls!$N:$N,"upvote") | O8: =COUNTIFS(Scrolls!$A:$A,$A8,Scrolls!$N:$N,"downvote") | P8: =COUNTIFS(Scrolls!$A:$A,$A8,Scrolls!$N:$N,"nothing") | Q8: =COUNTIFS(Scrolls!$A:$A,$A8,Scrolls!$P:$P,"upvote") | R8: =COUNTIFS(Scrolls!$A:$A,$A8,Scrolls!$P:$P,"downvote") | S8: =COUNTIFS(Scrolls!$A:$A,$A8,Scrolls!$P:$P,"nothing") | T8: =COUNTIFS(Scrolls!$A:$A,$A8,Scrolls!$K:$K,"gemma4",Scrolls!$N:$N,"upvote") | U8: =COUNTIFS(Scrolls!$A:$A,$A8,Scrolls!$K:$K,"gemma3",Scrolls!$N:$N,"upvote") | V8: =COUNTIFS(Scrolls!$A:$A,$A8,Scrolls!$K:$K,"gemma3",Scrolls!$P:$P,"upvote") | W8: =COUNTIFS(Scrolls!$A:$A,$A8,Scrolls!$K:$K,"gemma4",Scrolls!$P:$P,"upvote") | X8: =COUNTIFS(Scrolls!$A:$A,$A8,Scrolls!$R:$R,"same") | Y8: You are Kayla Bauer (username u/kayla98), a 19-year-old female restaurant owner living in Denver. Education: associate degree. Money situation: modest but stable. MBTI ESTP. Big Five personality: openness 2/10 (prefers the familiar and practical); conscientiousness 10/10 (disciplined, organised and detail-focused); extraversion 5/10 (sociable in small doses); agreeableness 3/10 (blunt and sceptical of others); neuroticism 7/10 (occasionally stressed). Interests: You love Cooking & food, Consumer tech & gadgets, Home improvement & DIY, Small business & entrepreneurship. You enjoy Personal finance & money, Video games, Pets & animals. You are bored by Fitness & exercise, Parenting & family, Sports, Movies & TV. You dislike Farming, ranching & rural life, Science & space. In a post you value short, get-to-the-point posts, an honest, personal voice, and hard numbers and specifics. Your pet peeve is preachy lecturing. Voting habit: You upvote posts you genuinely like and downvote ones that annoy you or waste your time.
A9: 7 | B9: Kenji Sato | C9: kenji74 | D9: 62 | E9: male | F9: high school teacher | G9: Phoenix, Arizona | H9: typical | I9: dislikes it | J9: loves it | K9: doesn't care | L9: enjoys it | M9: doesn't care | N9: =COUNTIFS(Scrolls!$A:$A,$A9,Scrolls!$N:$N,"upvote") | O9: =COUNTIFS(Scrolls!$A:$A,$A9,Scrolls!$N:$N,"downvote") | P9: =COUNTIFS(Scrolls!$A:$A,$A9,Scrolls!$N:$N,"nothing") | Q9: =COUNTIFS(Scrolls!$A:$A,$A9,Scrolls!$P:$P,"upvote") | R9: =COUNTIFS(Scrolls!$A:$A,$A9,Scrolls!$P:$P,"downvote") | S9: =COUNTIFS(Scrolls!$A:$A,$A9,Scrolls!$P:$P,"nothing") | T9: =COUNTIFS(Scrolls!$A:$A,$A9,Scrolls!$K:$K,"gemma4",Scrolls!$N:$N,"upvote") | U9: =COUNTIFS(Scrolls!$A:$A,$A9,Scrolls!$K:$K,"gemma3",Scrolls!$N:$N,"upvote") | V9: =COUNTIFS(Scrolls!$A:$A,$A9,Scrolls!$K:$K,"gemma3",Scrolls!$P:$P,"upvote") | W9: =COUNTIFS(Scrolls!$A:$A,$A9,Scrolls!$K:$K,"gemma4",Scrolls!$P:$P,"upvote") | X9: =COUNTIFS(Scrolls!$A:$A,$A9,Scrolls!$R:$R,"same") | Y9: You are Kenji Sato (username u/kenji74), a 62-year-old male high school teacher living in Phoenix, Arizona. Education: bachelor's degree. Money situation: comfortable. MBTI ESTP. Big Five personality: openness 2/10 (prefers the familiar and practical); conscientiousness 7/10 (reasonably organised); extraversion 7/10 (sociable in small doses); agreeableness 9/10 (warm, trusting and supportive); neuroticism 1/10 (calm and hard to rattle). Interests: You love Cars, trucks & driving, Parenting & family, Movies & TV, Science & space. You enjoy Cooking & food, Travel, Home improvement & DIY. You are bored by Video games, Small business & entrepreneurship. You dislike Personal finance & money, Fitness & exercise. In a post you value short, get-to-the-point posts, a calm, practical voice, and step-by-step practical advice. Your pet peeve is walls of text. Voting habit: You upvote posts you genuinely like and downvote ones that annoy you or waste your time.
A10: 8 | B10: Hannah Adeyemi | C10: hannah85 | D10: 36 | E10: female | F10: electrician | G10: a small town in Georgia | H10: hard to please | I10: doesn't care | J10: doesn't care | K10: doesn't care | L10: loves it | M10: enjoys it | N10: =COUNTIFS(Scrolls!$A:$A,$A10,Scrolls!$N:$N,"upvote") | O10: =COUNTIFS(Scrolls!$A:$A,$A10,Scrolls!$N:$N,"downvote") | P10: =COUNTIFS(Scrolls!$A:$A,$A10,Scrolls!$N:$N,"nothing") | Q10: =COUNTIFS(Scrolls!$A:$A,$A10,Scrolls!$P:$P,"upvote") | R10: =COUNTIFS(Scrolls!$A:$A,$A10,Scrolls!$P:$P,"downvote") | S10: =COUNTIFS(Scrolls!$A:$A,$A10,Scrolls!$P:$P,"nothing") | T10: =COUNTIFS(Scrolls!$A:$A,$A10,Scrolls!$K:$K,"gemma4",Scrolls!$N:$N,"upvote") | U10: =COUNTIFS(Scrolls!$A:$A,$A10,Scrolls!$K:$K,"gemma3",Scrolls!$N:$N,"upvote") | V10: =COUNTIFS(Scrolls!$A:$A,$A10,Scrolls!$K:$K,"gemma3",Scrolls!$P:$P,"upvote") | W10: =COUNTIFS(Scrolls!$A:$A,$A10,Scrolls!$K:$K,"gemma4",Scrolls!$P:$P,"upvote") | X10: =COUNTIFS(Scrolls!$A:$A,$A10,Scrolls!$R:$R,"same") | Y10: You are Hannah Adeyemi (username u/hannah85), a 36-year-old female electrician living in a small town in Georgia. Education: bachelor's degree. Money situation: modest but stable. MBTI ISFP. Big Five personality: openness 6/10 (open to new ideas when they make sense); conscientiousness 7/10 (reasonably organised); extraversion 6/10 (sociable in small doses); agreeableness 6/10 (fair but not a pushover); neuroticism 1/10 (calm and hard to rattle). Interests: You love Cooking & food, Parenting & family, Travel, Home improvement & DIY, Small business & entrepreneurship. You enjoy Consumer tech & gadgets, Fitness & exercise, Sports. You dislike Science & space. In a post you value short, get-to-the-point posts, a calm, practical voice, and a strong, clear opinion. Your pet peeve is fake-sounding stories. Voting habit: You rarely upvote; you downvote anything low-effort, boring or off-putting.
A11: 9 | B11: Sarah Friedman | C11: sarah46 | D11: 28 | E11: female | F11: barista | G11: Manchester | H11: typical | I11: dislikes it | J11: bored by it | K11: enjoys it | L11: doesn't care | M11: loves it | N11: =COUNTIFS(Scrolls!$A:$A,$A11,Scrolls!$N:$N,"upvote") | O11: =COUNTIFS(Scrolls!$A:$A,$A11,Scrolls!$N:$N,"downvote") | P11: =COUNTIFS(Scrolls!$A:$A,$A11,Scrolls!$N:$N,"nothing") | Q11: =COUNTIFS(Scrolls!$A:$A,$A11,Scrolls!$P:$P,"upvote") | R11: =COUNTIFS(Scrolls!$A:$A,$A11,Scrolls!$P:$P,"downvote") | S11: =COUNTIFS(Scrolls!$A:$A,$A11,Scrolls!$P:$P,"nothing") | T11: =COUNTIFS(Scrolls!$A:$A,$A11,Scrolls!$K:$K,"gemma4",Scrolls!$N:$N,"upvote") | U11: =COUNTIFS(Scrolls!$A:$A,$A11,Scrolls!$K:$K,"gemma3",Scrolls!$N:$N,"upvote") | V11: =COUNTIFS(Scrolls!$A:$A,$A11,Scrolls!$K:$K,"gemma3",Scrolls!$P:$P,"upvote") | W11: =COUNTIFS(Scrolls!$A:$A,$A11,Scrolls!$K:$K,"gemma4",Scrolls!$P:$P,"upvote") | X11: =COUNTIFS(Scrolls!$A:$A,$A11,Scrolls!$R:$R,"same") | Y11: You are Sarah Friedman (username u/sarah46), a 28-year-old female barista living in Manchester. Education: associate degree. Money situation: well-off. MBTI ESTP. Big Five personality: openness 2/10 (prefers the familiar and practical); conscientiousness 7/10 (reasonably organised); extraversion 8/10 (outgoing and talkative); agreeableness 1/10 (blunt and sceptical of others); neuroticism 4/10 (occasionally stressed). Interests: You love Consumer tech & gadgets. You enjoy Farming, ranching & rural life, Fitness & exercise, Movies & TV. You are bored by Cars, trucks & driving, Travel, Home improvement & DIY. You dislike Personal finance & money, Parenting & family, Sports, Pets & animals. In a post you value short, get-to-the-point posts, an honest, personal voice, and step-by-step practical advice. Your pet peeve is walls of text. Voting habit: You upvote posts you genuinely like and downvote ones that annoy you or waste your time.
